<?xml version="1.0"?>
<robot name="humanoid">
  
  <!-- Base (Torso) -->
  <link name="torso">
    <inertial>
      <origin xyz="0 0 0"/>
      <mass value="50"/>  <!-- Approximate upper body weight -->
      <inertia ixx="1" iyy="1" izz="1" ixy="0" ixz="0" iyz="0"/>
    </inertial>
    <visual>
      <geometry>
        <capsule radius="0.2" length="0.6"/>
      </geometry>
      <material name="blue">
        <color rgba="0 0 1 1"/>
      </material>
    </visual>
    <collision>
      <geometry>
        <capsule radius="0.2" length="0.6"/>
      </geometry>
    </collision>
  </link>

  <!-- Head -->
  <link name="head">
    <inertial>
      <origin xyz="0 0 0.2"/>
      <mass value="5"/>
      <inertia ixx="0.1" iyy="0.1" izz="0.1" ixy="0" ixz="0" iyz="0"/>
    </inertial>
    <visual>
      <geometry>
        <sphere radius="0.15"/>
      </geometry>
      <material name="skin">
        <color rgba="0.9 0.8 0.6 1"/>
      </material>
    </visual>
    <collision>
      <geometry>
        <sphere radius="0.15"/>
      </geometry>
    </collision>
  </link>

  <joint name="neck" type="fixed">
    <parent link="torso"/>
    <child link="head"/>
    <origin xyz="0 0 0.45"/>
  </joint>

  <!-- Left Arm -->
  <link name="left_upper_arm">
    <inertial>
      <origin xyz="0 0 0"/>
      <mass value="3"/>
      <inertia ixx="0.05" iyy="0.05" izz="0.05" ixy="0" ixz="0" iyz="0"/>
    </inertial>
    <visual>
      <geometry>
        <capsule radius="0.08" length="0.4"/>
      </geometry>
      <material name="blue"/>
    </visual>
    <collision>
      <geometry>
        <capsule radius="0.08" length="0.4"/>
      </geometry>
    </collision>
  </link>

  <joint name="left_shoulder" type="revolute">
    <parent link="torso"/>
    <child link="left_upper_arm"/>
    <origin xyz="-0.25 0 0.35"/>
    <axis xyz="0 0 1"/>
    <limit lower="-1.57" upper="1.57" effort="10" velocity="1"/>
  </joint>

  <!-- Right Arm -->
  <link name="right_upper_arm">
    <inertial>
      <origin xyz="0 0 0"/>
      <mass value="3"/>
      <inertia ixx="0.05" iyy="0.05" izz="0.05" ixy="0" ixz="0" iyz="0"/>
    </inertial>
    <visual>
      <geometry>
        <capsule radius="0.08" length="0.4"/>
      </geometry>
      <material name="blue"/>
    </visual>
    <collision>
      <geometry>
        <capsule radius="0.08" length="0.4"/>
      </geometry>
    </collision>
  </link>

  <joint name="right_shoulder" type="revolute">
    <parent link="torso"/>
    <child link="right_upper_arm"/>
    <origin xyz="0.25 0 0.35"/>
    <axis xyz="0 0 1"/>
    <limit lower="-1.57" upper="1.57" effort="10" velocity="1"/>
  </joint>

  <!-- Left Leg -->
  <link name="left_upper_leg">
    <inertial>
      <origin xyz="0 0 0"/>
      <mass value="8"/>
      <inertia ixx="0.2" iyy="0.2" izz="0.2" ixy="0" ixz="0" iyz="0"/>
    </inertial>
    <visual>
      <geometry>
        <capsule radius="0.1" length="0.5"/>
      </geometry>
      <material name="blue"/>
    </visual>
    <collision>
      <geometry>
        <capsule radius="0.1" length="0.5"/>
      </geometry>
    </collision>
  </link>

  <joint name="left_hip" type="revolute">
    <parent link="torso"/>
    <child link="left_upper_leg"/>
    <origin xyz="-0.15 0 -0.35"/>
    <axis xyz="0 1 0"/>
    <limit lower="-1.57" upper="1.57" effort="50" velocity="1"/>
  </joint>

  <!-- Right Leg -->
  <link name="right_upper_leg">
    <inertial>
      <origin xyz="0 0 0"/>
      <mass value="8"/>
      <inertia ixx="0.2" iyy="0.2" izz="0.2" ixy="0" ixz="0" iyz="0"/>
    </inertial>
    <visual>
      <geometry>
        <capsule radius="0.1" length="0.5"/>
      </geometry>
      <material name="blue"/>
    </visual>
    <collision>
      <geometry>
        <capsule radius="0.1" length="0.5"/>
      </geometry>
    </collision>
  </link>

  <joint name="right_hip" type="revolute">
    <parent link="torso"/>
    <child link="right_upper_leg"/>
    <origin xyz="0.15 0 -0.35"/>
    <axis xyz="0 1 0"/>
    <limit lower="-1.57" upper="1.57" effort="50" velocity="1"/>
  </joint>

</robot>
